Traceback (most recent call last):
  File "/home/callaram/.conda/envs/jupyterbook/lib/python3.10/site-packages/jupyter_cache/executors/utils.py", line 58, in single_nb_execution
    executenb(
  File "/home/callaram/.conda/envs/jupyterbook/lib/python3.10/site-packages/nbclient/client.py", line 1314, in execute
    return NotebookClient(nb=nb, resources=resources, km=km, **kwargs).execute()
  File "/home/callaram/.conda/envs/jupyterbook/lib/python3.10/site-packages/jupyter_core/utils/__init__.py", line 165, in wrapped
    return loop.run_until_complete(inner)
  File "/home/callaram/.conda/envs/jupyterbook/lib/python3.10/asyncio/base_events.py", line 646, in run_until_complete
    return future.result()
  File "/home/callaram/.conda/envs/jupyterbook/lib/python3.10/site-packages/nbclient/client.py", line 709, in async_execute
    await self.async_execute_cell(
  File "/home/callaram/.conda/envs/jupyterbook/lib/python3.10/site-packages/nbclient/client.py", line 1062, in async_execute_cell
    await self._check_raise_for_error(cell, cell_index, exec_reply)
  File "/home/callaram/.conda/envs/jupyterbook/lib/python3.10/site-packages/nbclient/client.py", line 918, in _check_raise_for_error
    raise CellExecutionError.from_cell_and_msg(cell, exec_reply_content)
nbclient.exceptions.CellExecutionError: An error occurred while executing the following cell:
------------------
git switch new-branch
echo -en "\nThis is the fifth line." >> file1.txt
git switch main
------------------

----- stdout -----
Switched to branch 'new-branch'
----- stdout -----
error: Your local changes to the following files would be overwritten by checkout:
----- stdout -----
	file1.txt
----- stdout -----
Please commit your changes or stash them before you switch branches.
----- stdout -----
Aborting
------------------



